File: sample heat/Ag_ZF_300_to_0.35K_165_90mg.dat
[Header]
TITLE,Ag_ZF_300_to_0.35K_165_90mg.dat
BYAPP,HeatCapacity,2.7.2,1.5
INFO,169.90,MASS:Sample Mass (mg)
INFO,0,MASSERR:Sample Mass Error (mg)
INFO,107.8682 ,MOLWGHT:Formula Weight (g/mole)
INFO,0,ATOMS:Atoms per Formula Unit
INFO,PPMS Heat Capacity Option 2.7.2 Build 2,APPNAME
DATATYPE,TIME,1
STARTUPAXIS, X, 7, LINEAR, AUTO
STARTUPAXIS, Y1, 9, LINEAR, AUTO
[Data]
Time Stamp (Seconds),PPMS Status (Code),Puck Temp (Kelvin),System Temp (Kelvin),Field (Oersted),Pressure (Torr),Sample Temp (Kelvin),Temp Rise (Kelvin),Samp HC (µJ/K),Samp HC Err (µJ/K),Addenda HC (µJ/K),Addenda HC Err (µJ/K),Total HC (µJ/K),Total HC Err (µJ/K),Fit Deviation (ChiSquare),Time Const tau1 (seconds),Time Const tau2 (seconds),Sample Coupling (Percent),Debye Temp (Kelvin),Debye Temp Err (Kelvin),Cal Correction (Factor),Therm Resist (Ohms),Htr Resist (Ohms),Puck Resist (Ohms),Wire Cond (W/K),Meas Time (seconds),Temp Squared (K^2),Samp HC/Temp (µJ/K/K),Addenda Offset HC (µJ/K)
24071075.66,5905,0,295.001,0.092,0.0003531,298.56898,6.2804809,39350.41,13.79,10845.236,3.154,50195.645,13.79,0.34313164,446.468,0.12637054,99.832827,0,0,1,,,,0.00011254,515.5305,89143.434,131.79671,0,,,
24077384.47,5905,0,295.005,0.092,0.0003574,298.20767,5.6342572,39349.823,14.96,10833.383,3.144,50183.206,14.96,0.14022802,448.69163,0.11447642,99.849225,0,0,1,,,,0.00011195,447.9858,88927.813,131.95443,0,,,
24085738.52,5905,0,281.875,0.092,0.0003705,284.99888,5.4748608,39278.406,14.62,10431.441,2.979,49709.847,14.62,0.15950502,499.88375,0.12702623,99.846688,0,0,1,,,,9.9538E-5,499.294,81224.359,137.81951,0,,,
24094513.31,5905,0,269.333,0.092,0.000403,272.22035,5.0552701,39108.144,16.15,10020.775,2.979,49128.919,16.15,0.17045448,551.77703,0.1178672,99.86839,0,0,1,,,,8.9112E-5,499.7771,74103.917,143.66356,0,,,
24102270.3,5905,0,269.322,0.092,0.000403,272.37373,5.2878988,39110.177,13.2,10025.916,2.979,49136.093,13.2,0.13913618,548.01744,0.10930719,99.877147,0,0,1,,,,8.9731E-5,549.2289,74187.451,143.59012,0,,,
24112143.66,5905,0,257.346,0.092,0.000403,260.2921,5.1266072,38790.223,15.63,9606.6535,2.927,48396.876,15.63,0.30102934,600.09806,0.12082499,99.873401,0,0,1,,,,8.0714E-5,603.1726,67751.977,149.02574,0,,,
24122385.48,5905,0,245.902,0.092,0.0003934,248.60248,4.7511555,38683.604,11.65,9166.1807,2.742,47849.785,11.65,1.5319781,654.37964,0.094736801,99.90649,0,0,1,,,,7.3167E-5,598.7116,61803.195,155.60426,0,,,
24131572.09,5905,0,245.897,0.092,0.0004079,248.68838,4.8907807,38669.995,14.44,9169.2055,2.744,47839.201,14.44,0.16111749,649.38364,0.090337899,99.910185,0,0,1,,,,7.3712E-5,651.4936,61845.91,155.49579,0,,,
24142975.19,5905,0,234.938,0.092,0.0004384,237.6318,4.7248306,38418.395,11.25,8726.5446,2.53,47144.94,11.25,1.5229089,705.44895,0.096419514,99.909361,0,0,1,,,,6.687E-5,708.3356,56468.874,161.67194,0,,,
24154809.17,5905,0,224.502,0.092,0.0004944,227.03459,4.489042,37885.705,13.92,8281.8477,2.337,46167.553,13.92,0.09546938,757.16662,0.07477568,99.932897,0,0,1,,,,6.1002E-5,707.0733,51544.706,166.87195,0,,,
24165482.86,5905,0,224.499,0.092,0.0003982,227.05302,4.5518021,37874.677,15.86,8282.0944,2.337,46156.771,15.86,0.28564905,755.60443,0.11186815,99.899412,0,0,1,,,,6.1127E-5,761.28,51553.075,166.80983,0,,,
24178443.52,5905,0,214.511,0.092,0.000375,216.95353,4.3651964,37565.473,14,7841.376,2.202,45406.849,14,0.092321754,812.88458,0.078293624,99.932568,0,0,1,,,,5.5885E-5,812.4187,47068.834,173.14986,0,,,
24191845.05,5905,0,204.958,0.092,0.0003617,207.27938,4.1690683,37313.446,15.58,7407.0931,2.155,44720.539,15.58,0.044414808,867.7541,0.073682096,99.938543,0,0,1,,,,5.1558E-5,812.425,42964.743,180.01523,0,,,
24204028.19,5905,0,204.975,0.092,0.000366,207.28239,4.172938,37303.09,13.27,7406.4693,2.155,44709.559,13.27,0.31057602,869.08908,0.096731039,99.919447,0,0,1,,,,5.1473E-5,865.8115,42965.987,179.96266,0,,,
24218650.75,5905,0,195.846,0.092,0.0003447,198.07375,4.0034184,37225.234,15.06,6979.8201,2.208,44205.054,15.06,0.099934276,923.277,0.088528095,99.927866,0,0,1,,,,4.7903E-5,924.3253,39233.21,187.93623,0,,,
24233696.69,5905,0,187.116,0.092,0.0003934,189.29296,3.8602288,36986.057,16.72,6561.7119,2.305,43547.769,16.72,0.038549916,978.65245,0.069686079,99.944345,0,0,1,,,,4.4516E-5,925.9672,35831.824,195.39056,0,,,
24247452.11,5905,0,187.135,0.092,0.000403,189.28303,3.8363282,36955.242,13.25,6560.2971,2.305,43515.539,13.25,0.16134364,977.2079,0.077866157,99.937746,0,0,1,,,,4.455E-5,980.2692,35828.066,195.23801,0,,,
24263462.91,5905,0,178.801,0.092,0.000366,180.81675,3.5705644,36805.975,13.33,6144.2334,2.393,42950.209,13.33,0.09193407,1031.3675,0.059935631,99.952585,0,0,1,,,,4.1658E-5,1000,32694.697,203.55402,0,,,
24279637.73,5905,0,170.842,0.092,0.0003617,172.81007,3.4630481,36486.738,15.56,5741.3254,2.428,42228.063,15.56,0.05293321,1082.7686,0.085028292,99.933131,0,0,1,,,,3.902E-5,1000,29863.32,211.1378,0,,,
24293683.88,5905,0,170.847,0.092,0.0003841,172.70996,3.2792244,36498.097,17.25,5734.7263,2.428,42232.823,17.25,0.042289097,1085.4672,0.098197077,99.92288,0,0,1,,,,3.893E-5,1000,29828.73,211.32595,0,,,
24310291.22,5905,0,163.257,0.092,0.0003531,164.97589,3.0220799,36119.907,19.16,5331.4851,2.397,41451.392,19.16,0.030225036,1135.1279,0.35709345,99.718903,0,0,1,,,,3.6595E-5,1000,27217.043,218.94052,0,,,
24327990.28,5905,0,155.979,0.092,0.0003982,157.65015,2.9037953,35753.707,15.55,4935.6702,2.336,40689.377,15.55,0.18443749,1191.8591,0.38751016,99.694453,0,0,1,,,,3.422E-5,1000,24853.568,226.79146,0,,,
24342038.39,5905,0,155.968,0.092,0.000375,157.60405,2.7910396,35740.106,24.13,4932.0504,2.336,40672.156,24.13,0.022446546,1186.5666,0.3930698,99.688594,0,0,1,,,,3.436E-5,1000,24839.036,226.7715,0,,,
24359765.77,5905,0,149.056,0.092,0.0003574,150.55489,2.5887092,35324.88,23.15,4543.5774,2.251,39868.458,23.15,0.025958943,1234.2533,0.44736122,99.64031,0,0,1,,,,3.2393E-5,1000,22666.776,234.63123,0,,,
24377525.44,5905,0,142.408,0.092,0.0003531,143.84178,2.4952385,34975.7,17.64,4175.0705,2.145,39150.771,17.64,0.051412753,1289.0933,0.45617609,99.627723,0,0,1,,,,3.0461E-5,1000,20690.457,243.15397,0,,,
24392574.36,5905,0,142.412,0.092,0.0003447,143.8023,2.3961677,34950.456,21.82,4171.8508,2.144,39122.306,21.82,0.014625868,1273.9242,0.4470412,99.630826,0,0,1,,,,3.0801E-5,1000,20679.101,243.04518,0,,,
24418369.95,5905,0,136.069,0.092,0.0003795,137.36801,2.2215681,34600.263,29.74,3824.0153,2.018,38424.278,29.74,0.0061024896,1313.8456,0.48840528,99.584112,0,0,1,,,,2.9345E-5,1000,18869.971,251.88006,0,,,
24445132.52,5905,0,130.019,0.092,0.0003531,131.23108,2.0748431,34150.048,19.49,3495.1852,1.861,37645.233,19.49,0.020205713,1363.9925,0.53017862,99.537115,0,0,1,,,,2.7705E-5,1000,17221.596,260.22836,0,,,
24461184.78,5905,0,130.015,0.092,0.0003207,131.22787,2.0726349,34160.857,15.43,3495.0222,1.861,37655.88,15.43,0.069368353,1366.7831,0.54602609,99.524071,0,0,1,,,,2.7659E-5,1000,17220.755,260.31708,0,,,
24487933.09,5905,0,124.241,0.092,0.0003365,125.37497,1.936398,33697.93,24.81,3181.0542,1.683,36878.984,24.81,0.017933501,1403.5888,0.58019384,99.473673,0,0,1,,,,2.6391E-5,1000,15718.883,268.77717,0,,,
24515670.75,5905,0,118.719,0.092,0.0003574,119.80238,1.8145249,33227.423,19.52,2886.5846,1.506,36114.008,19.52,0.02272893,1440.7167,0.59562626,99.435619,0,0,1,,,,2.5187E-5,1000,14352.609,277.35195,0,,,
24531725.17,5905,0,118.704,0.092,0.0003489,119.80343,1.8118779,33217.636,18.15,2886.6088,1.506,36104.245,18.15,0.025220082,1435.2178,0.61149396,99.418442,0,0,1,,,,2.5281E-5,1000,14352.861,277.26783,0,,,
24559455.77,5905,0,113.428,0.092,0.0003447,114.47102,1.6996215,32738.839,21.87,2613.0125,1.348,35351.851,21.87,0.015861728,1477.6421,0.64498996,99.359375,0,0,1,,,,2.4057E-5,1000,13103.614,286.00112,0,,,
24586176.72,5905,0,108.373,0.092,0.000366,109.37452,1.5954015,32184.9,23.46,2361.6888,1.223,34546.589,23.46,0.021821975,1504.5554,0.67704677,99.289721,0,0,1,,,,2.3104E-5,1000,11962.785,294.26324,0,,,
24602225.22,5905,0,108.376,0.092,0.0003617,109.3743,1.5928252,32175.164,17.62,2361.6213,1.223,34536.785,17.62,0.022895091,1496.4684,0.66716227,99.29651,0,0,1,,,,2.3221E-5,1000,11962.738,294.1748,0,,,
24629895.19,5905,0,103.563,0.092,0.0003447,104.50001,1.4974207,31630.14,24.75,2126.3691,1.121,33756.509,24.75,0.011415767,1531.683,0.69647641,99.225052,0,0,1,,,,2.219E-5,1000,10920.252,302.68073,0,,,
24657571.77,5905,0,98.9505,0.092,0.0003531,99.838497,1.4093083,31044.579,25.2,1907.3197,1.032,32951.898,25.2,0.0078680491,1552.2469,0.7122199,99.153017,0,0,1,,,,2.139E-5,1000,9967.7256,310.94798,0,,,
24673635.89,5905,0,98.9481,0.092,0.0003934,99.834981,1.4090378,31016.752,25.05,1907.1651,1.032,32923.917,25.05,0.011880459,1551.6709,0.72420184,99.138976,0,0,1,,,,2.1382E-5,1000,9967.0234,310.6802,0,,,
24701300.92,5905,0,94.535,0.092,0.0003447,95.351315,1.3274114,30399.894,28.37,1704.8804,0.9508,32104.775,28.37,0.0051529036,1574.0324,0.72820416,99.073111,0,0,1,,,,2.0568E-5,1000,9091.8733,318.81988,0,,,
24728970.27,5905,0,90.3334,0.092,0.0003531,91.081658,1.2563908,29659.756,20.47,1522.4449,0.8743,31182.201,20.47,0.012543175,1587.1882,0.73601089,98.993242,0,0,1,,,,1.9827E-5,1000,8295.8684,325.63918,0,,,
24766103.36,5905,0,83.8972,0.092,0.0003246,84.585356,1.1498103,28501.908,25.91,1263.4285,0.7562,29765.337,25.91,0.0080088985,1618.1941,0.74444765,98.857197,0,0,1,,,,1.8589E-5,1000,7154.6825,336.96031,0,,,
24805521.73,5905,0,72.8953,0.092,0.0003531,73.515227,0.98484806,26069.57,20.62,873.27618,0.5695,26942.846,20.62,0.013089258,1634.0252,0.69599231,98.62532,0,0,1,,,,1.6704E-5,1000,5404.4887,354.61455,0,,,
24846627.61,5905,0,63.3403,0.092,0.000366,63.897001,0.87045772,23288.392,22.49,599.2025,0.4554,23887.594,22.49,0.016052022,1596.3187,0.59704079,98.44889,0,0,1,,,,1.5188E-5,1000,4082.8267,364.46768,0,,,
24886449.88,5905,0,55.0434,0.092,0.0003447,55.537417,0.79937531,20198.63,15.45,408.88115,0.2926,20607.511,15.45,0.042676965,1526.5784,0.49202293,98.316545,0,0,1,,,,1.3721E-5,1000,3084.4047,363.69409,0,,,
24924967.03,5905,0,47.831,0.092,0.0003531,48.271866,0.7501785,17108.957,11.44,282.08536,0.2001,17391.043,11.44,0.30806211,1421.0633,0.39406393,98.232931,0,0,1,,,,1.2451E-5,1000,2330.173,354.42917,0,,,
24954188.53,5905,0,41.5593,0.092,0.0003574,42.000113,0.76178081,14014.419,13.55,199.00774,0.1751,14213.426,13.55,0.27982786,1268.6562,0.31690604,98.158506,0,0,1,,,,1.1408E-5,1000,1764.0095,333.67574,0,,,
24974138.11,5905,0,36.1098,0.092,0.0003705,36.547274,0.73660214,11084.034,11.83,141.77384,0.1684,11225.808,11.83,7.394731,1099.5259,0.25270559,98.123396,0,0,1,,,,1.04E-5,1000,1335.7033,303.27937,0,,,
24991902.08,5905,0,31.3784,0.092,0.0003365,31.797298,0.72693542,8424.3458,12.26,102.16821,0.1657,8526.514,12.26,3.5657558,923.75108,0.20407285,98.099514,0,0,1,,,,9.4049E-6,1000,1011.0681,264.93905,0,,,
25009170.41,5905,0,26.7257,0.092,0.0003406,27.074958,0.65526247,5880.6851,9.911,70.947464,0.1205,5951.6325,9.911,6.9727302,729.62393,0.16094908,98.092467,0,0,1,,,,8.312E-6,832.4588,733.05334,217.20016,0,,,
25020831.61,5905,0,22.305,0.092,0.0003489,22.620636,0.55629008,3710.4062,6.789,47.120159,0.06897,3757.5263,6.789,2.5075953,532.66607,0.120611,98.138474,0,0,1,,,,7.1847E-6,626.2269,511.69316,164.02749,0,,,
25029335.84,5905,0,18.6225,0.092,0.0003365,18.944224,0.47029163,2254.0455,4.775,31.047158,0.03687,2285.0926,4.775,3.8131639,373.92432,0.092058842,98.129882,0,0,1,,,,6.2245E-6,451.7433,358.88361,118.98326,0,,,
25035444.86,5905,0,15.5438,0.092,0.0003406,15.879012,0.39277293,1284.9852,3.015,20.281093,0.02729,1305.2663,3.015,1.4920237,258.31327,0.071697987,98.153398,0,0,1,,,,5.1452E-6,312.4942,252.14302,80.923498,0,,,
25039866.02,5905,0,12.9804,0.092,0.0003169,13.323571,0.32457851,716.92582,1.713,13.155951,0.02946,730.08177,1.713,1.7367247,177.51486,0.055557628,98.20119,0,0,1,,,,4.1855E-6,213.7837,177.51755,53.808832,0,,,
25043990.38,5905,0,10.8396,0.092,0.0003365,11.171393,0.26525726,403.76693,0.9467,8.4130265,0.02032,412.17996,0.9467,0.48756564,123.96191,0.041713674,98.29008,0,0,1,,,,3.3806E-6,147.9124,124.80002,36.142936,0,,,
25046325.64,5905,0,9.0626,0.092,0.0003285,9.3776362,0.21248996,231.94019,0.4652,5.3626341,0.0137,237.30282,0.4652,1.6703881,87.612586,0.030452044,98.403101,0,0,1,,,,2.7506E-6,101.9117,87.94006,24.733332,0,,,
25048483.75,5905,0,7.5522,0.092,0.0003169,7.8391494,0.18689025,134.34884,0.5061,3.3536565,0.01226,137.70249,0.5061,0.1146817,70.371213,0.026138059,98.414033,0,0,1,,,,1.9868E-6,77.373,61.452264,17.138191,0,,,
25050173.39,5905,0,6.2979,0.092,0.0003207,6.5617986,0.15651003,78.806564,0.1961,2.0752546,0.009456,80.881819,0.1961,2.5079253,50.541453,0.018210705,98.539511,0,0,1,,,,1.6228E-6,58.1962,43.057201,12.009903,0,,,
25051328.08,5905,0,5.2577,0.092,0.0003207,5.4837024,0.13131636,46.645915,0.1062,1.2588233,0.004889,47.904738,0.1062,1.3897863,38.418805,0.013122613,98.648679,0,0,1,,,,1.2631E-6,43.8721,30.070992,8.5062812,0,,,
25052398.91,5905,0,4.3914,0.092,0.0003169,4.5700982,0.10891572,28.394362,0.08219,0.74531429,0.002589,29.139676,0.08219,0.080850701,29.288254,0.0091142734,98.737023,0,0,1,,,,1.007E-6,33.74291,20.885798,6.2130747,0,,,
25053810.67,5905,0,3.6646,0.092,0.0003207,3.7910612,0.089153713,17.46601,0.0376,0.42956745,0.001154,17.895577,0.0376,1.4068445,23.226705,0.0065122858,98.789949,0,0,1,,,,7.7947E-7,25.92558,14.372145,4.6071558,0,,,
25054985.48,5905,0,3.0594,0.092,0.0003131,3.1465161,0.074459085,10.902062,0.04045,0.2465704,0.0007716,11.148633,0.04045,0.20914995,17.88393,0.0042685586,98.885039,0,0,1,,,,6.3011E-7,20.72363,9.9005638,3.4648041,0,,,
25056010.27,5905,0,2.5573,0.092,0.0003131,2.5874238,0.059812771,7.0767933,0.02293,0.13888477,0.0007423,7.2156781,0.02293,2.6788442,15.131827,0.0032305224,98.856962,0,0,1,,,,4.8216E-7,16.48384,6.694762,2.7350731,0,,,
25057097.88,5905,0,2.1317,0.092,0.0003207,2.1192593,0.049637568,4.6884025,0.02265,0.080252262,0.0004363,4.7686547,0.02265,1.8409173,12.662723,0.0023196447,98.881161,0,0,1,,,,3.8071E-7,13.85901,4.4912599,2.2122836,0,,,
25057779.73,5905,0,1.779,0.092,0.0003093,1.7219357,0.038049654,3.3090402,0.01368,0.047663943,0.0003785,3.3567041,0.01368,0.59444137,10.749843,0.0017727865,98.808473,0,0,1,,,,3.1592E-7,11.59065,2.9650626,1.9216979,0,,,
25058372.25,5905,0,1.485,0.092,0.0003207,1.3977427,0.029017355,2.4253768,0.01225,0.029516273,0.000263,2.454893,0.01225,1.4347592,9.5176323,0.0014589891,98.693256,0,0,1,,,,2.6127E-7,10.06904,1.9536846,1.7352098,0,,,
25058868.63,5905,0,1.2391,0.092,0.0003093,1.1343523,0.021793786,1.8327496,0.007642,0.019146646,0.0001482,1.8518963,0.007642,1.5229773,8.6099748,0.0012395726,98.573425,0,0,1,,,,2.1814E-7,8.885508,1.2867552,1.6156793,0,,,
25059359,5905,0,1.0348,0.092,0.0003325,0.92968404,0.017792246,1.3734026,0.008579,0.013578538,0.0002423,1.3869811,0.008579,1.2287482,7.8856085,0.0012009514,98.404497,0,0,1,,,,1.7868E-7,8.164104,0.86431242,1.4772789,0,,,
25059822.3,5905,0,0.864,0.092,0.0003325,0.75419769,0.013264798,1.1071393,0.005098,0.010078775,0.0001688,1.1172181,0.005098,0.77693318,7.3263009,0.0011983471,98.136868,0,0,1,,,,1.5534E-7,7.459337,0.56881416,1.4679697,0,,,
25060281.83,5905,0,0.7211,0.092,0.0003169,0.61134881,0.010167889,0.89101805,0.003182,0.0077484536,9.735E-5,0.8987665,0.003182,0.60465859,7.0458816,0.0012898062,97.811902,0,0,1,,,,1.3036E-7,7.038935,0.37374737,1.4574626,0,,,
25060776.78,5905,0,0.602,0.092,0.0003365,0.49567835,0.012991671,0.71137346,0.002026,0.0060992956,9.379E-5,0.71747275,0.002026,0.14536087,6.7621251,0.0014588433,97.373752,0,0,1,,,,1.0892E-7,6.891046,0.24569703,1.4351514,0,,,
25061290.2,5905,0,0.5022,0.092,0.0003489,0.3906233,0.012052372,0.51607833,0.001628,0.0047191786,0.0001011,0.5207975,0.001628,0.12558012,6.6125099,0.0017942696,96.884395,0,0,1,,,,8.1247E-8,6.733884,0.15258656,1.3211663,0,,,
25062101.38,5905,0,0.4201,0.092,0.0003574,0.30157255,0.0090746163,0.45290239,0.001485,0.0032010133,-3.603E-5,0.4561034,0.001485,0.26040772,6.4750183,0.001685427,96.118182,0,0,1,,,,7.3246E-8,6.459728,0.090946003,1.5018024,0,,,
25063314.81,5905,0,0.3501,0.092,0.0003489,0.35320745,0.007663693,0.36426115,0.001522,0.0041189076,6.158E-5,0.36838006,0.001522,0.11259296,6.4302712,0.0033824605,95.002856,0,0,1,,,,6.0236E-8,6.593906,0.1247555,1.0312952,0,,,
25095690.44,5905,0,0.393,0.092,0.0003447,0.27428304,0.0081171628,0.44731705,0.001868,0.0026718934,-0.0001049,0.44998895,0.001868,0.10015199,6.6473348,0.0015945829,95.760085,0,0,1,,,,7.0657E-8,6.603844,0.075231184,1.6308593,0,,,
25096093.19,5910,0,0.5418,0.092,0.0003285,0.3840462,0.01170387,0.50710129,0.001485,0.0046219766,9.693E-5,0.51172326,0.001485,0.40308614,6.7380107,0.0018677106,96.8045,0,0,1,,,,7.8408E-8,6.502856,0.14749148,1.3204174,0,,,
25096654.47,5905,0,0.6268,0.092,0.0003285,0.52033856,0.01319942,0.75497793,0.002007,0.0064397884,9.315E-5,0.76141772,0.002007,0.57944886,6.9581305,0.0014137881,97.517493,0,0,1,,,,1.1217E-7,6.82231,0.27075222,1.450936,0,,,
25097158.11,5905,0,0.7917,0.092,0.0003325,0.68100967,0.011486304,0.98729224,0.004672,0.0088291612,0.0001106,0.9961214,0.004672,0.17278389,7.3676837,0.0012451588,98.039097,0,0,1,,,,1.3786E-7,6.995251,0.46377417,1.4497478,0,,,
25097648.72,5905,0,0.9998,0.092,0.0003365,0.89173932,0.015797563,1.3242072,0.00895,0.01275963,0.0002661,1.3369668,0.00895,2.1301262,7.7922891,0.0010839888,98.506876,0,0,1,,,,1.7413E-7,7.506925,0.79519902,1.4849711,0,,,
25100609.53,5905,0,1.3891,0.092,0.0003093,1.2938999,0.025730192,2.1911389,0.009634,0.025067142,0.0002368,2.216206,0.009634,1.1447882,8.9756734,0.0012397688,98.749915,0,0,1,,,,2.4997E-7,9.540732,1.6741771,1.6934377,0,,,
25102539.34,5905,0,1.1926,0.092,0.0002157,1.1733262,0.00090092079,0.10374935,0.07267,0.020343138,0.0001658,0.12409249,0.07267,0.27257796,0.0080643996,0,100,0,0,1,,,,1.5388E-5,0.09311642,1.3766944,0.088423275,0,,,
25102954.92,5905,0,1.0234,0.092,0.0001912,1.0372769,0.00044184469,0.085849909,0.0001476,0.016108375,0.0001476,0.10195828,0,1.1616442,0.0045545911,0,100,0,0,1,,,,2.2386E-5,0.08184077,1.0759434,0.082764696,0,,,
25103815.2,5905,0,0.8777,0.092,0.0001468,0.8682055,0.00047173907,0.23035192,0.129,0.012213018,0.0002695,0.24256494,0.129,1.3742871,0.030669134,0,100,0,0,1,,,,7.9091E-6,0.07493951,0.75378078,0.26531958,0,,,
25104217,5905,0,0.7533,0.092,0.0001504,0.76289031,0.00037122235,0.09434642,0.0426,0.010192881,0.0001763,0.1045393,0.0426,0.44209385,0.0083882748,0,100,0,0,1,,,,1.2463E-5,0.06992498,0.58200163,0.12366971,0,,,
25104779.28,5905,0,0.6465,0.092,0.0001578,0.60513377,0.00028118975,0.11201432,9.703E-5,0.00763175,9.703E-5,0.11964607,0,1.656063,0.013384117,0,100,0,0,1,,,,8.9394E-6,0.0666418,0.36618688,0.18510671,0,,,
25105315.14,5905,0,0.5539,0.092,0.0001716,0.44297482,0.00030797113,-0.0029823517,0.0009294,0.0053951652,0.0001073,0.0024128135,0.0009231,0.2581497,0.00029733466,0,100,0,0,1,,,,8.1148E-6,0.06480169,0.19622669,-0.0067325534,0,,,
25105774.61,5905,0,0.4754,0.092,0.0001912,0.3643491,0.00058456026,0.0028542424,0.003301,0.0042805632,7.526E-5,0.0071348057,0.0033,0.19035056,0.0023100447,0,100,0,0,1,,,,3.0886E-6,0.06405558,0.13275027,0.0078338122,0,,,
25107946.61,5905,0,0.408,0.092,0.0002678,0.2882557,0.00057195993,0.0035247519,0.001605,0.002915171,-7.224E-5,0.006439923,0.001604,0.44916973,0.0027966238,0,100,0,0,1,,,,2.3027E-6,0.06434667,0.083091348,0.012227866,0,,,
25108419.16,5905,0,0.3502,0.092,0.0002776,0.35052028,0.00065263645,0.0011285053,0.001173,0.004048373,5.522E-5,0.0051768783,0.001172,0.19900348,0.003601355,0,100,0,0,1,,,,1.4375E-6,0.06267014,0.12286447,0.003219515,0,,,
25115395.88,5905,0,1.389,0.092,0.0003447,1.2850777,0.019242117,2.9743181,0.02116,0.024673522,0.0002327,2.9989917,0.02116,1.6602958,9.4061246,0.0015937803,97.879894,0,0,1,,,,3.2563E-7,9.720949,1.6514246,2.3145046,0,,,
25115944.39,5905,0,1.1921,0.092,0.0003489,1.0836987,0.016339755,2.3121096,0.01455,0.017517018,0.0001354,2.3296266,0.01455,0.85464654,8.94002,0.0014841037,97.725268,0,0,1,,,,2.6656E-7,9.242133,1.1744028,2.1335355,0,,,
25116423.83,5905,0,1.0231,0.092,0.0003447,0.91997885,0.014125337,1.7311287,0.01574,0.013355634,0.0002504,1.7444844,0.01574,1.0645736,8.0118849,0.0014387828,97.579385,0,0,1,,,,2.2306E-7,8.402456,0.84636109,1.8817049,0,,,
25116877.78,5905,0,0.877,0.092,0.0003705,0.76880033,0.012350533,1.3685063,0.006794,0.010335863,0.0001859,1.3788422,0.006794,1.2802118,8.6068087,0.0011380411,98.190964,0,0,1,,,,1.6311E-7,8.092705,0.59105395,1.7800543,0,,,
25117344.27,5905,0,0.7532,0.092,0.0003531,0.6433946,0.010986745,1.1242303,0.003904,0.0082343323,0.0001005,1.1324646,0.003904,0.46928983,8.5364157,0.0011932359,98.02562,0,0,1,,,,1.353E-7,8.645836,0.41395662,1.7473418,0,,,
25117821.89,5905,0,0.646,0.092,0.0003406,0.53973726,0.013671438,0.94476674,0.002148,0.0067194143,9.523E-5,0.95148616,0.002148,0.36239518,8.176263,0.0013324959,97.620805,0,0,1,,,,1.1917E-7,8.340015,0.29131631,1.7504197,0,,,
25118324.72,5905,0,0.5541,0.092,0.0003617,0.44648037,0.012571202,0.72584669,0.002005,0.0054672553,0.0001061,0.73131395,0.002005,0.63413179,8.0462017,0.0016004067,97.245702,0,0,1,,,,9.3426E-8,7.98308,0.19934472,1.625708,0,,,
25118917.47,5905,0,0.4752,0.092,0.0003447,0.36072511,0.011358014,0.58161189,0.001812,0.0042526917,7.302E-5,0.58586458,0.001812,0.20979387,7.7848097,0.0017635913,96.753781,0,0,1,,,,7.7746E-8,8.021718,0.1301226,1.612341,0,,,
25120870.91,5905,0,0.408,0.092,0.0003574,0.28930901,0.0086744155,0.53417357,0.00163,0.0029671223,-6.548E-5,0.53714069,0.00163,0.27404027,7.8251697,0.0016503328,96.004515,0,0,1,,,,7.1469E-8,7.753883,0.083699703,1.8463772,0,,,
25121387.92,5905,0,0.3503,0.092,0.0003489,0.35329004,0.0075293343,0.43421649,0.001574,0.0041201672,6.169E-5,0.43833666,0.001574,0.13691939,7.696507,0.0033611837,95.075729,0,0,1,,,,5.9849E-8,7.660219,0.12481385,1.2290652,0,,,
25130980.69,5905,0,8.8573,0.092,0.0003531,9.0689803,0.0055642055,16.829027,4.359,4.8716865,0.01281,21.700714,4.359,1.4837315,0.097715002,0,100,0,0,1,,,,0.00022208,1.780545,82.246403,1.8556692,0,,,
25131830.19,5905,0,6.9475,0.092,0.0003285,7.1655352,0.0041506663,13.225162,4.459,2.6107009,0.01174,15.835863,4.459,1.5908935,0.091406097,0,100,0,0,1,,,,0.00017325,1.281236,51.344895,1.8456629,0,,,
25136123.36,5905,0,10.0154,0.092,0.0003447,10.219715,0.0064470728,17.245144,4.843,6.6320377,0.0165,23.877182,4.843,1.0242206,0.095402905,0,100,0,0,1,,,,0.00025028,2.091742,104.44258,1.6874388,0,,,
25137019.13,5905,0,7.8488,0.092,0.0002984,8.078324,0.004907128,15.101228,3.451,3.594893,0.01216,18.696121,3.451,1.4943147,0.097016951,0,100,0,0,1,,,,0.00019271,1.513568,65.259318,1.8693516,0,,,
25137870.98,5905,0,6.1627,0.092,0.000302,6.3675081,0.0035504902,13.017423,3.995,1.8917995,0.008358,14.909222,3.995,1.2813125,0.098085869,0,100,0,0,1,,,,0.000152,1.078268,40.54516,2.0443512,0,,,
25138526.06,5905,0,4.8304,0.092,0.0002878,4.9882184,0.0026422929,7.9039465,2.213,0.95091898,0.003518,8.8548655,2.213,2.3491166,0.075846197,0,100,0,0,1,,,,0.00011675,0.7423081,24.882323,1.5845229,0,,,
25139462.73,5905,0,3.7814,0.092,0.0002878,3.8814611,0.0018588259,4.2666424,1.311,0.45583859,0.001252,4.722481,1.311,2.9279675,0.050281103,0,100,0,0,1,,,,9.3922E-5,0.4968391,15.06574,1.0992362,0,,,
25140287.59,5905,0,2.9833,0.092,0.000302,3.0319792,0.0014541,1.7035853,1.022,0.2186609,0.0008023,1.9222462,1.022,1.5662591,0.028041131,0,100,0,0,1,,,,6.8551E-5,0.3261578,9.1928981,0.56187236,0,,,
25141125.48,5905,0,2.3391,0.092,0.000302,2.3211776,0.0013537557,0.56794005,0.1939,0.10164315,0.0005132,0.66958321,0.1939,1.3252953,0.016026135,0,100,0,0,1,,,,4.1781E-5,0.2168919,5.3878655,0.24467755,0,,,
25142353.31,5905,0,1.8332,0.092,0.0002984,1.7654359,0.00079703644,0.56326821,0.0004003,0.050251242,0.0004003,0.61351945,0,0.40518817,0.015670735,0,100,0,0,1,,,,3.9151E-5,0.151461,3.116764,0.31905333,0,,,
25176959.53,5905,10.0062,10.0056,0.092,0.0003093,10.225631,0.035923345,304.78226,14.98,6.6508449,0.01654,311.43311,14.98,5.150008,14.394991,0,100,0,0,1,,,,2.1635E-5,19.15386,104.56353,29.805717,0,,,
25180628.81,5905,8.92255,8.9215,0.092,0.000302,9.2033395,0.15975707,217.78632,0.4706,5.099354,0.0132,222.88567,0.4706,0.11575024,68.637548,0.029601491,98.035639,0,0,1,,,,3.3094E-6,73.22178,84.701459,23.663836,0,,,
25182818.97,5905,7.09312,7.0931,0.092,0.000302,7.3768225,0.16978512,112.29787,0.3096,2.8502066,0.01215,115.14808,0.3096,0.13920875,59.149056,0.021146147,98.498638,0,0,1,,,,1.975E-6,69.49563,54.41751,15.223068,0,,,
25184214.09,5905,5.61138,5.6118,0.092,0.0003131,5.85526,0.14359746,56.327721,0.1251,1.5143013,0.00611,57.842022,0.1251,7.1889322,42.361097,0.014820406,98.610358,0,0,1,,,,1.3837E-6,50.36577,34.28407,9.6200204,0,,,
25185423.86,5905,4.45551,4.4555,0.092,0.0003207,4.6386858,0.11304034,29.548654,0.07074,0.77850723,0.002744,30.327162,0.07074,0.28357032,30.164107,0.009549048,98.719531,0,0,1,,,,1.0178E-6,35.43689,21.517406,6.3700487,0,,,
25186994.13,5905,3.53305,3.533,0.092,0.0003207,3.6521068,0.087462686,15.884949,0.03592,0.38437885,0.001,16.269328,0.03592,0.26877336,21.673476,0.0056976269,98.848337,0,0,1,,,,7.59E-7,25.63039,13.337884,4.3495303,0,,,
25188183.91,5905,2.80545,2.8055,0.092,0.0003246,2.8649275,0.068770218,8.8399817,0.03213,0.18707325,0.0008337,9.027055,0.03213,0.16716517,16.325939,0.0035455594,98.919133,0,0,1,,,,5.5872E-7,19.23848,8.2078098,3.0855865,0,,,
25189268.58,5905,2.22558,2.2258,0.092,0.0003325,2.2185558,0.051472922,5.2152559,0.01511,0.090732794,0.000459,5.3059887,0.01511,0.67135748,13.2164,0.0025168273,98.854751,0,0,1,,,,4.0596E-7,14.6081,4.92199,2.3507436,0,,,
25189958.14,5905,1.76611,1.7661,0.092,0.0003246,1.7076687,0.038417011,3.266072,0.01303,0.046707651,0.0003697,3.3127796,0.01303,0.46967169,10.680554,0.0017322443,98.82007,0,0,1,,,,3.1377E-7,11.84265,2.9161324,1.9125911,0,,,
25190469.86,5905,1.40204,1.402,0.092,0.0003406,1.3079619,0.026423206,2.2219187,0.01026,0.025652497,0.0002418,2.2475712,0.01026,2.0292204,9.1809814,0.0013467848,98.683331,0,0,1,,,,2.48E-7,9.714362,1.7107643,1.6987641,0,,,
25191015.31,5905,1.11196,1.112,0.092,0.0003447,1.0124101,0.020209759,1.4986172,0.01101,0.015542504,0.0001632,1.5141597,0.01101,1.1019895,8.2612772,0.0012937441,98.435024,0,0,1,,,,1.8614E-7,8.504003,1.0249742,1.4802471,0,,,
25191499.77,5905,0.881738,0.8817,0.092,0.0003285,0.77241212,0.013888932,1.1366952,0.005302,0.010405157,0.0001905,1.1471004,0.005302,0.93371048,7.3954778,0.0012131169,98.141751,0,0,1,,,,1.5799E-7,7.679982,0.59662048,1.4716175,0,,,
25191984.69,5905,0.699993,0.7,0.092,0.0003285,0.59058486,0.0098861032,0.8571077,0.003376,0.0074424557,9.671E-5,0.86455015,0.003376,0.3578067,6.9482354,0.0012601436,97.829373,0,0,1,,,,1.2714E-7,7.09765,0.34879047,1.4512863,0,,,
25192497.66,5905,0.55573,0.5557,0.092,0.0003406,0.44871962,0.012854793,0.61173923,0.00191,0.0054959963,0.0001056,0.61723523,0.00191,0.24856069,6.8589601,0.001652412,97.194031,0,0,1,,,,9.2542E-8,6.851764,0.2013493,1.3632995,0,,,
25193250.59,5905,0.441065,0.441,0.092,0.0003406,0.32345658,0.010105547,0.46216637,0.00162,0.0036069972,1.092E-5,0.46577337,0.00162,0.27200543,6.5971651,0.0017918979,96.33482,0,0,1,,,,7.3247E-8,6.626618,0.10462416,1.4288359,0,,,
25194455.06,5905,0.35023,0.3502,0.092,0.0003447,0.35333125,0.0075905728,0.36274978,0.00128,0.0041205364,6.172E-5,0.36687032,0.00128,0.11017992,6.371525,0.0032944988,95.115344,0,0,1,,,,6.0472E-8,6.505487,0.12484298,1.0266564,0,,,